Workbook

Sheet Cover
B2: EXCEL SHEETS
B3: supporting paper "Financial Sustainability of the Care for the Disabled: A Simulation of Benefits for Older People in the Baltic States up to 2036 with data from SHARE and Eurostat"
B5: Author: Hans Gevers - Junior Research Fellow at the Estonian Business School
B6: https://orcid.org/0009-0001-0249-4142 hans.gevers@ebs.ee
B9: Conventions:
B10: Description | C10: Code | D10: Note
B11: Hard-coded numbers | C11: Blue
B12: Formulas/calculations | C12: Black
B13: Interpolated within | C13: Green | D13: Time average of the preceding and subsequent value (first available)
B14: Interpolated across | C14: Dark red | D14: Cross-sectionl average of the preceding and subsequent value (first available)
B15: Linked to online content | C15: Red
B16: Linked to other sheet | C16: Orange

Sheet Content
B2: Countries: | C2: Estonia, Latvia, Lithuania
B4: Sheet
B5: 5 | C5: Open in Data Browser | D5: Population in Numbers on January 1 per Age and Gender Group 2008-2025 (annual)
B6: 6 | C6: Open in Data Browser | D6: Percentage of Disabled per Age and Gender group 2008-2025 (annual)
B7: 7 | C7: Open in Data Browser | D7: Mean Equivalised Income as Purchasing Power Standard per Age and Gender Group 2008-2025 (annual)
B8: 9 | D8: Input data from Poisson regressions + Mean income from SHARE sample per age, gender, disability, and country group
B9: 10 | D9: Forecast amount for disability benefits and pensions in euros for the Population: per Age, Gender, and Disability Group (annual)

Sheet Error checking
A1: Sheet 6: Population check: Total for Estonia
B2: =SUM(Population!U3,Population!U6,Population!U9,Population!U12,Population!U15,Population!U18,Population!U21,Population!U24,Population!U27,Population!U30,Population!U33,Population!U36,Population!U39,Population!U42,Population!U45,Population!U48,Population!U51,Population!U54) -> 643995 | C2: citizens older than 45
B3: =B2/1300000 -> 0.49538077 | C3: of total population as the used sample older than 45
B4: =SUM(Population!AF59,Population!AF62,Population!AF65,Population!AF68,Population!AF71,Population!AF74,Population!AF77,Population!AF80,Population!AF83,Population!AF86) -> 679090 | C4: estimated citizens older than 45 in 2036
B5: =B4/B2-1 -> 0.054495765 | C5: increase in population estimated to be older than 45 in 2036
A7: Sheet 7: Check if the percentage totals 100 for disability within age, gender, and country
B8: 2008 | C8: 2009 | D8: 2010 | E8: 2011 | F8: 2012 | G8: 2013 | H8: 2014 | I8: 2015 | J8: 2016 | K8: 2017 | L8: 2018 | M8: 2019 | N8: 2020 | O8: 2021 | P8: 2022 | Q8: 2023 | R8: 2024 | S8: 2025
B9: =IF((Disability!E3+Disability!E6)=100,"ok","nok") -> ok | C9: =IF((Disability!F3+Disability!F6)=100,"ok","nok") -> ok | D9: =IF((Disability!G3+Disability!G6)=100,"ok","nok") -> ok | E9: =IF((Disability!H3+Disability!H6)=100,"ok","nok") -> ok | F9: =IF((Disability!I3+Disability!I6)=100,"ok","nok") -> ok | G9: =IF((Disability!J3+Disability!J6)=100,"ok","nok") -> ok | H9: =IF((Disability!K3+Disability!K6)=100,"ok","nok") -> ok | I9: =IF((Disability!L3+Disability!L6)=100,"ok","nok") -> ok | ... S9: =IF((Disability!V3+Disability!V6)=100,"ok","nok") -> ok
B10: =IF((Disability!E4+Disability!E7)=100,"ok","nok") -> ok | C10: =IF((Disability!F4+Disability!F7)=100,"ok","nok") -> ok | D10: =IF((Disability!G4+Disability!G7)=100,"ok","nok") -> ok | E10: =IF((Disability!H4+Disability!H7)=100,"ok","nok") -> ok | F10: =IF((Disability!I4+Disability!I7)=100,"ok","nok") -> ok | G10: =IF((Disability!J4+Disability!J7)=100,"ok","nok") -> ok | H10: =IF((Disability!K4+Disability!K7)=100,"ok","nok") -> ok | I10: =IF((Disability!L4+Disability!L7)=100,"ok","nok") -> ok | ... S10: =IF((Disability!V4+Disability!V7)=100,"ok","nok") -> ok
B11: =IF((Disability!E5+Disability!E8)=100,"ok","nok") -> ok | C11: =IF((Disability!F5+Disability!F8)=100,"ok","nok") -> ok | D11: =IF((Disability!G5+Disability!G8)=100,"ok","nok") -> ok | E11: =IF((Disability!H5+Disability!H8)=100,"ok","nok") -> ok | F11: =IF((Disability!I5+Disability!I8)=100,"ok","nok") -> ok | G11: =IF((Disability!J5+Disability!J8)=100,"ok","nok") -> ok | H11: =IF((Disability!K5+Disability!K8)=100,"ok","nok") -> ok | I11: =IF((Disability!L5+Disability!L8)=100,"ok","nok") -> ok | ... S11: =IF((Disability!V5+Disability!V8)=100,"ok","nok") -> ok
B12: =IF((Disability!E9+Disability!E12)=100,"ok","nok") -> ok | C12: =IF((Disability!F9+Disability!F12)=100,"ok","nok") -> ok | D12: =IF((Disability!G9+Disability!G12)=100,"ok","nok") -> ok | E12: =IF((Disability!H9+Disability!H12)=100,"ok","nok") -> ok | F12: =IF((Disability!I9+Disability!I12)=100,"ok","nok") -> ok | G12: =IF((Disability!J9+Disability!J12)=100,"ok","nok") -> ok | H12: =IF((Disability!K9+Disability!K12)=100,"ok","nok") -> ok | I12: =IF((Disability!L9+Disability!L12)=100,"ok","nok") -> ok | ... S12: =IF((Disability!V9+Disability!V12)=100,"ok","nok") -> ok
B13: =IF((Disability!E10+Disability!E13)=100,"ok","nok") -> ok | C13: =IF((Disability!F10+Disability!F13)=100,"ok","nok") -> ok | D13: =IF((Disability!G10+Disability!G13)=100,"ok","nok") -> ok | E13: =IF((Disability!H10+Disability!H13)=100,"ok","nok") -> ok | F13: =IF((Disability!I10+Disability!I13)=100,"ok","nok") -> ok | G13: =IF((Disability!J10+Disability!J13)=100,"ok","nok") -> ok | H13: =IF((Disability!K10+Disability!K13)=100,"ok","nok") -> ok | I13: =IF((Disability!L10+Disability!L13)=100,"ok","nok") -> ok | ... S13: =IF((Disability!V10+Disability!V13)=100,"ok","nok") -> ok
B14: =IF((Disability!E11+Disability!E14)=100,"ok","nok") -> ok | C14: =IF((Disability!F11+Disability!F14)=100,"ok","nok") -> ok | D14: =IF((Disability!G11+Disability!G14)=100,"ok","nok") -> ok | E14: =IF((Disability!H11+Disability!H14)=100,"ok","nok") -> ok | F14: =IF((Disability!I11+Disability!I14)=100,"ok","nok") -> ok | G14: =IF((Disability!J11+Disability!J14)=100,"ok","nok") -> ok | H14: =IF((Disability!K11+Disability!K14)=100,"ok","nok") -> ok | I14: =IF((Disability!L11+Disability!L14)=100,"ok","nok") -> ok | ... S14: =IF((Disability!V11+Disability!V14)=100,"ok","nok") -> ok
B15: =IF((Disability!E15+Disability!E18)=100,"ok","nok") -> ok | C15: =IF((Disability!F15+Disability!F18)=100,"ok","nok") -> ok | D15: =IF((Disability!G15+Disability!G18)=100,"ok","nok") -> ok | E15: =IF((Disability!H15+Disability!H18)=100,"ok","nok") -> ok | F15: =IF((Disability!I15+Disability!I18)=100,"ok","nok") -> ok | G15: =IF((Disability!J15+Disability!J18)=100,"ok","nok") -> ok | H15: =IF((Disability!K15+Disability!K18)=100,"ok","nok") -> ok | I15: =IF((Disability!L15+Disability!L18)=100,"ok","nok") -> ok | ... S15: =IF((Disability!V15+Disability!V18)=100,"ok","nok") -> ok
B16: =IF((Disability!E16+Disability!E19)=100,"ok","nok") -> ok | C16: =IF((Disability!F16+Disability!F19)=100,"ok","nok") -> ok | D16: =IF((Disability!G16+Disability!G19)=100,"ok","nok") -> ok | E16: =IF((Disability!H16+Disability!H19)=100,"ok","nok") -> ok | F16: =IF((Disability!I16+Disability!I19)=100,"ok","nok") -> ok | G16: =IF((Disability!J16+Disability!J19)=100,"ok","nok") -> ok | H16: =IF((Disability!K16+Disability!K19)=100,"ok","nok") -> ok | I16: =IF((Disability!L16+Disability!L19)=100,"ok","nok") -> ok | ... S16: =IF((Disability!V16+Disability!V19)=100,"ok","nok") -> ok
B17: =IF((Disability!E17+Disability!E20)=100,"ok","nok") -> ok | C17: =IF((Disability!F17+Disability!F20)=100,"ok","nok") -> ok | D17: =IF((Disability!G17+Disability!G20)=100,"ok","nok") -> ok | E17: =IF((Disability!H17+Disability!H20)=100,"ok","nok") -> ok | F17: =IF((Disability!I17+Disability!I20)=100,"ok","nok") -> ok | G17: =IF((Disability!J17+Disability!J20)=100,"ok","nok") -> ok | H17: =IF((Disability!K17+Disability!K20)=100,"ok","nok") -> ok | I17: =IF((Disability!L17+Disability!L20)=100,"ok","nok") -> ok | ... S17: =IF((Disability!V17+Disability!V20)=100,"ok","nok") -> ok
B18: =IF((Disability!E21+Disability!E24)=100,"ok","nok") -> ok | C18: =IF((Disability!F21+Disability!F24)=100,"ok","nok") -> ok | D18: =IF((Disability!G21+Disability!G24)=100,"ok","nok") -> ok | E18: =IF((Disability!H21+Disability!H24)=100,"ok","nok") -> ok | F18: =IF((Disability!I21+Disability!I24)=100,"ok","nok") -> ok | G18: =IF((Disability!J21+Disability!J24)=100,"ok","nok") -> ok | H18: =IF((Disability!K21+Disability!K24)=100,"ok","nok") -> ok | I18: =IF((Disability!L21+Disability!L24)=100,"ok","nok") -> ok | ... S18: =IF((Disability!V21+Disability!V24)=100,"ok","nok") -> ok
B19: =IF((Disability!E22+Disability!E25)=100,"ok","nok") -> ok | C19: =IF((Disability!F22+Disability!F25)=100,"ok","nok") -> ok | D19: =IF((Disability!G22+Disability!G25)=100,"ok","nok") -> ok | E19: =IF((Disability!H22+Disability!H25)=100,"ok","nok") -> ok | F19: =IF((Disability!I22+Disability!I25)=100,"ok","nok") -> ok | G19: =IF((Disability!J22+Disability!J25)=100,"ok","nok") -> ok | H19: =IF((Disability!K22+Disability!K25)=100,"ok","nok") -> ok | I19: =IF((Disability!L22+Disability!L25)=100,"ok","nok") -> ok | ... S19: =IF((Disability!V22+Disability!V25)=100,"ok","nok") -> ok
B20: =IF((Disability!E23+Disability!E26)=100,"ok","nok") -> ok | C20: =IF((Disability!F23+Disability!F26)=100,"ok","nok") -> ok | D20: =IF((Disability!G23+Disability!G26)=100,"ok","nok") -> ok | E20: =IF((Disability!H23+Disability!H26)=100,"ok","nok") -> ok | F20: =IF((Disability!I23+Disability!I26)=100,"ok","nok") -> ok | G20: =IF((Disability!J23+Disability!J26)=100,"ok","nok") -> ok | H20: =IF((Disability!K23+Disability!K26)=100,"ok","nok") -> ok | I20: =IF((Disability!L23+Disability!L26)=100,"ok","nok") -> ok | ... S20: =IF((Disability!V23+Disability!V26)=100,"ok","nok") -> ok
B21: =IF((Disability!E27+Disability!E30)=100,"ok","nok") -> ok | C21: =IF((Disability!F27+Disability!F30)=100,"ok","nok") -> ok | D21: =IF((Disability!G27+Disability!G30)=100,"ok","nok") -> ok | E21: =IF((Disability!H27+Disability!H30)=100,"ok","nok") -> ok | F21: =IF((Disability!I27+Disability!I30)=100,"ok","nok") -> ok | G21: =IF((Disability!J27+Disability!J30)=100,"ok","nok") -> ok | H21: =IF((Disability!K27+Disability!K30)=100,"ok","nok") -> ok | I21: =IF((Disability!L27+Disability!L30)=100,"ok","nok") -> ok | ... S21: =IF((Disability!V27+Disability!V30)=100,"ok","nok") -> ok
B22: =IF((Disability!E28+Disability!E31)=100,"ok","nok") -> ok | C22: =IF((Disability!F28+Disability!F31)=100,"ok","nok") -> ok | D22: =IF((Disability!G28+Disability!G31)=100,"ok","nok") -> ok | E22: =IF((Disability!H28+Disability!H31)=100,"ok","nok") -> ok | F22: =IF((Disability!I28+Disability!I31)=100,"ok","nok") -> ok | G22: =IF((Disability!J28+Disability!J31)=100,"ok","nok") -> ok | H22: =IF((Disability!K28+Disability!K31)=100,"ok","nok") -> ok | I22: =IF((Disability!L28+Disability!L31)=100,"ok","nok") -> ok | ... S22: =IF((Disability!V28+Disability!V31)=100,"ok","nok") -> ok
B23: =IF((Disability!E29+Disability!E32)=100,"ok","nok") -> ok | C23: =IF((Disability!F29+Disability!F32)=100,"ok","nok") -> ok | D23: =IF((Disability!G29+Disability!G32)=100,"ok","nok") -> ok | E23: =IF((Disability!H29+Disability!H32)=100,"ok","nok") -> ok | F23: =IF((Disability!I29+Disability!I32)=100,"ok","nok") -> ok | G23: =IF((Disability!J29+Disability!J32)=100,"ok","nok") -> ok | H23: =IF((Disability!K29+Disability!K32)=100,"ok","nok") -> ok | I23: =IF((Disability!L29+Disability!L32)=100,"ok","nok") -> ok | ... S23: =IF((Disability!V29+Disability!V32)=100,"ok","nok") -> ok
B24: =IF((Disability!E33+Disability!E36)=100,"ok","nok") -> ok | C24: =IF((Disability!F33+Disability!F36)=100,"ok","nok") -> ok | D24: =IF((Disability!G33+Disability!G36)=100,"ok","nok") -> ok | E24: =IF((Disability!H33+Disability!H36)=100,"ok","nok") -> ok | F24: =IF((Disability!I33+Disability!I36)=100,"ok","nok") -> ok | G24: =IF((Disability!J33+Disability!J36)=100,"ok","nok") -> ok | H24: =IF((Disability!K33+Disability!K36)=100,"ok","nok") -> ok | I24: =IF((Disability!L33+Disability!L36)=100,"ok","nok") -> ok | ... S24: =IF((Disability!V33+Disability!V36)=100,"ok","nok") -> ok
B25: =IF((Disability!E34+Disability!E37)=100,"ok","nok") -> ok | C25: =IF((Disability!F34+Disability!F37)=100,"ok","nok") -> ok | D25: =IF((Disability!G34+Disability!G37)=100,"ok","nok") -> ok | E25: =IF((Disability!H34+Disability!H37)=100,"ok","nok") -> ok | F25: =IF((Disability!I34+Disability!I37)=100,"ok","nok") -> ok | G25: =IF((Disability!J34+Disability!J37)=100,"ok","nok") -> ok | H25: =IF((Disability!K34+Disability!K37)=100,"ok","nok") -> ok | I25: =IF((Disability!L34+Disability!L37)=100,"ok","nok") -> ok | ... S25: =IF((Disability!V34+Disability!V37)=100,"ok","nok") -> ok
B26: =IF((Disability!E35+Disability!E38)=100,"ok","nok") -> ok | C26: =IF((Disability!F35+Disability!F38)=100,"ok","nok") -> ok | D26: =IF((Disability!G35+Disability!G38)=100,"ok","nok") -> ok | E26: =IF((Disability!H35+Disability!H38)=100,"ok","nok") -> ok | F26: =IF((Disability!I35+Disability!I38)=100,"ok","nok") -> ok | G26: =IF((Disability!J35+Disability!J38)=100,"ok","nok") -> ok | H26: =IF((Disability!K35+Disability!K38)=100,"ok","nok") -> ok | I26: =IF((Disability!L35+Disability!L38)=100,"ok","nok") -> ok | ... S26: =IF((Disability!V35+Disability!V38)=100,"ok","nok") -> ok
B27: =IF((Disability!E39+Disability!E42)=100,"ok","nok") -> ok | C27: =IF((Disability!F39+Disability!F42)=100,"ok","nok") -> ok | D27: =IF((Disability!G39+Disability!G42)=100,"ok","nok") -> ok | E27: =IF((Disability!H39+Disability!H42)=100,"ok","nok") -> ok | F27: =IF((Disability!I39+Disability!I42)=100,"ok","nok") -> ok | G27: =IF((Disability!J39+Disability!J42)=100,"ok","nok") -> ok | H27: =IF((Disability!K39+Disability!K42)=100,"ok","nok") -> ok | I27: =IF((Disability!L39+Disability!L42)=100,"ok","nok") -> ok | ... S27: =IF((Disability!V39+Disability!V42)=100,"ok","nok") -> ok
B28: =IF((Disability!E40+Disability!E43)=100,"ok","nok") -> ok | C28: =IF((Disability!F40+Disability!F43)=100,"ok","nok") -> ok | D28: =IF((Disability!G40+Disability!G43)=100,"ok","nok") -> ok | E28: =IF((Disability!H40+Disability!H43)=100,"ok","nok") -> ok | F28: =IF((Disability!I40+Disability!I43)=100,"ok","nok") -> ok | G28: =IF((Disability!J40+Disability!J43)=100,"ok","nok") -> ok | H28: =IF((Disability!K40+Disability!K43)=100,"ok","nok") -> ok | I28: =IF((Disability!L40+Disability!L43)=100,"ok","nok") -> ok | ... S28: =IF((Disability!V40+Disability!V43)=100,"ok","nok") -> ok
B29: =IF((Disability!E41+Disability!E44)=100,"ok","nok") -> ok | C29: =IF((Disability!F41+Disability!F44)=100,"ok","nok") -> ok | D29: =IF((Disability!G41+Disability!G44)=100,"ok","nok") -> ok | E29: =IF((Disability!H41+Disability!H44)=100,"ok","nok") -> ok | F29: =IF((Disability!I41+Disability!I44)=100,"ok","nok") -> ok | G29: =IF((Disability!J41+Disability!J44)=100,"ok","nok") -> ok | H29: =IF((Disability!K41+Disability!K44)=100,"ok","nok") -> ok | I29: =IF((Disability!L41+Disability!L44)=100,"ok","nok") -> ok | ... S29: =IF((Disability!V41+Disability!V44)=100,"ok","nok") -> ok
B30: =IF((Disability!E45+Disability!E48)=100,"ok","nok") -> ok | C30: =IF((Disability!F45+Disability!F48)=100,"ok","nok") -> ok | D30: =IF((Disability!G45+Disability!G48)=100,"ok","nok") -> ok | E30: =IF((Disability!H45+Disability!H48)=100,"ok","nok") -> ok | F30: =IF((Disability!I45+Disability!I48)=100,"ok","nok") -> ok | G30: =IF((Disability!J45+Disability!J48)=100,"ok","nok") -> ok | H30: =IF((Disability!K45+Disability!K48)=100,"ok","nok") -> ok | I30: =IF((Disability!L45+Disability!L48)=100,"ok","nok") -> ok | ... S30: =IF((Disability!V45+Disability!V48)=100,"ok","nok") -> ok
B31: =IF((Disability!E46+Disability!E49)=100,"ok","nok") -> ok | C31: =IF((Disability!F46+Disability!F49)=100,"ok","nok") -> ok | D31: =IF((Disability!G46+Disability!G49)=100,"ok","nok") -> ok | E31: =IF((Disability!H46+Disability!H49)=100,"ok","nok") -> ok | F31: =IF((Disability!I46+Disability!I49)=100,"ok","nok") -> ok | G31: =IF((Disability!J46+Disability!J49)=100,"ok","nok") -> ok | H31: =IF((Disability!K46+Disability!K49)=100,"ok","nok") -> ok | I31: =IF((Disability!L46+Disability!L49)=100,"ok","nok") -> ok | ... S31: =IF((Disability!V46+Disability!V49)=100,"ok","nok") -> ok
B32: =IF((Disability!E47+Disability!E50)=100,"ok","nok") -> ok | C32: =IF((Disability!F47+Disability!F50)=100,"ok","nok") -> ok | D32: =IF((Disability!G47+Disability!G50)=100,"ok","nok") -> ok | E32: =IF((Disability!H47+Disability!H50)=100,"ok","nok") -> ok | F32: =IF((Disability!I47+Disability!I50)=100,"ok","nok") -> ok | G32: =IF((Disability!J47+Disability!J50)=100,"ok","nok") -> ok | H32: =IF((Disability!K47+Disability!K50)=100,"ok","nok") -> ok | I32: =IF((Disability!L47+Disability!L50)=100,"ok","nok") -> ok | ... S32: =IF((Disability!V47+Disability!V50)=100,"ok","nok") -> ok
B33: =IF((Disability!E51+Disability!E54)=100,"ok","nok") -> ok | C33: =IF((Disability!F51+Disability!F54)=100,"ok","nok") -> ok | D33: =IF((Disability!G51+Disability!G54)=100,"ok","nok") -> ok | E33: =IF((Disability!H51+Disability!H54)=100,"ok","nok") -> ok | F33: =IF((Disability!I51+Disability!I54)=100,"ok","nok") -> ok | G33: =IF((Disability!J51+Disability!J54)=100,"ok","nok") -> ok | H33: =IF((Disability!K51+Disability!K54)=100,"ok","nok") -> ok | I33: =IF((Disability!L51+Disability!L54)=100,"ok","nok") -> ok | ... S33: =IF((Disability!V51+Disability!V54)=100,"ok","nok") -> ok
B34: =IF((Disability!E52+Disability!E55)=100,"ok","nok") -> ok | C34: =IF((Disability!F52+Disability!F55)=100,"ok","nok") -> ok | D34: =IF((Disability!G52+Disability!G55)=100,"ok","nok") -> ok | E34: =IF((Disability!H52+Disability!H55)=100,"ok","nok") -> ok | F34: =IF((Disability!I52+Disability!I55)=100,"ok","nok") -> ok | G34: =IF((Disability!J52+Disability!J55)=100,"ok","nok") -> ok | H34: =IF((Disability!K52+Disability!K55)=100,"ok","nok") -> ok | I34: =IF((Disability!L52+Disability!L55)=100,"ok","nok") -> ok | ... S34: =IF((Disability!V52+Disability!V55)=100,"ok","nok") -> ok
B35: =IF((Disability!E53+Disability!E56)=100,"ok","nok") -> ok | C35: =IF((Disability!F53+Disability!F56)=100,"ok","nok") -> ok | D35: =IF((Disability!G53+Disability!G56)=100,"ok","nok") -> ok | E35: =IF((Disability!H53+Disability!H56)=100,"ok","nok") -> ok | F35: =IF((Disability!I53+Disability!I56)=100,"ok","nok") -> ok | G35: =IF((Disability!J53+Disability!J56)=100,"ok","nok") -> ok | H35: =IF((Disability!K53+Disability!K56)=100,"ok","nok") -> ok | I35: =IF((Disability!L53+Disability!L56)=100,"ok","nok") -> ok | ... S35: =IF((Disability!V53+Disability!V56)=100,"ok","nok") -> ok
B36: =IF((Disability!E57+Disability!E60)=100,"ok","nok") -> ok | C36: =IF((Disability!F57+Disability!F60)=100,"ok","nok") -> ok | D36: =IF((Disability!G57+Disability!G60)=100,"ok","nok") -> ok | E36: =IF((Disability!H57+Disability!H60)=100,"ok","nok") -> ok | F36: =IF((Disability!I57+Disability!I60)=100,"ok","nok") -> ok | G36: =IF((Disability!J57+Disability!J60)=100,"ok","nok") -> ok | H36: =IF((Disability!K57+Disability!K60)=100,"ok","nok") -> ok | I36: =IF((Disability!L57+Disability!L60)=100,"ok","nok") -> ok | ... S36: =IF((Disability!V57+Disability!V60)=100,"ok","nok") -> ok
B37: =IF((Disability!E58+Disability!E61)=100,"ok","nok") -> ok | C37: =IF((Disability!F58+Disability!F61)=100,"ok","nok") -> ok | D37: =IF((Disability!G58+Disability!G61)=100,"ok","nok") -> ok | E37: =IF((Disability!H58+Disability!H61)=100,"ok","nok") -> ok | F37: =IF((Disability!I58+Disability!I61)=100,"ok","nok") -> ok | G37: =IF((Disability!J58+Disability!J61)=100,"ok","nok") -> ok | H37: =IF((Disability!K58+Disability!K61)=100,"ok","nok") -> ok | I37: =IF((Disability!L58+Disability!L61)=100,"ok","nok") -> ok | ... S37: =IF((Disability!V58+Disability!V61)=100,"ok","nok") -> ok
B38: =IF((Disability!E59+Disability!E62)=100,"ok","nok") -> ok | C38: =IF((Disability!F59+Disability!F62)=100,"ok","nok") -> ok | D38: =IF((Disability!G59+Disability!G62)=100,"ok","nok") -> ok | E38: =IF((Disability!H59+Disability!H62)=100,"ok","nok") -> ok | F38: =IF((Disability!I59+Disability!I62)=100,"ok","nok") -> ok | G38: =IF((Disability!J59+Disability!J62)=100,"ok","nok") -> ok | H38: =IF((Disability!K59+Disability!K62)=100,"ok","nok") -> ok | I38: =IF((Disability!L59+Disability!L62)=100,"ok","nok") -> ok | ... S38: =IF((Disability!V59+Disability!V62)=100,"ok","nok") -> ok

Sheet FORECASTS >>>
B2: FORECAST SHEETS

Sheet Population
A1: Population in Numbers per Age and Gender Group 2008-2025 (annual) | D1: 2008 | E1: 2009 | F1: 2010 | G1: 2011 | H1: 2012 | I1: 2013 | J1: 2014 | K1: 2015 | L1: 2016 | M1: 2017 | N1: 2018 | O1: 2019 | P1: 2020 | Q1: 2021 | R1: 2022 | S1: 2023 | T1: 2024 | U1: 2025 | V1: 2026 | W1: 2027 | X1: 2028 | Y1: 2029 | Z1: 2030 | AA1: 2031 | AB1: 2032 | AC1: 2033 | AD1: 2034 | AE1: 2035 | AF1: 2036
A2: Age group | B2: Gender | C2: Country
A3: 45-49 | B3: males | C3: Estonia | D3: 46490 | E3: 45970 | F3: 45360 | G3: 44100 | H3: 42900 | I3: 41693 | J3: 41553 | K3: 41717 | L3: 42355 | M3: 43563 | N3: 45169 | O3: 46055 | P3: 46427 | Q3: 46677 | R3: 46714 | S3: 47550 | T3: 47886 | U3: 48027
C4: Latvia | D4: 78392 | E4: 76313 | F4: 74009 | G4: 70880 | H4: 68362 | I4: 66577 | J4: 65271 | K4: 64561 | L4: 64393 | M4: 64266 | N4: 64411 | O4: 64157 | P4: 64157 | Q4: 63622 | R4: 62894 | S4: 60434 | T4: 60139 | U4: 59882
C5: Lithuania | D5: 122232 | E5: 120465 | F5: 116956 | G5: 111656 | H5: 107123 | I5: 104020 | J5: 102256 | K5: 101129 | L5: 100479 | M5: 100052 | N5: 99115 | O5: 97568 | P5: 96512 | Q5: 93631 | R5: 91871 | S5: 93206 | T5: =AVERAGE(S5,U5) -> 95185.5 | U5: 97165
A6: 45-49 | B6: females | C6: Estonia | D6: 50350 | E6: 49370 | F6: 48310 | G6: 46680 | H6: 44885 | I6: 43639 | J6: 43137 | K6: 43075 | L6: 43499 | M6: 44308 | N6: 45053 | O6: 45292 | P6: 45307 | Q6: 44861 | R6: 44632 | S6: 45834 | T6: 46341 | U6: 46132
C7: Latvia | D7: 86948 | E7: 84858 | F7: 82049 | G7: 78141 | H7: 75062 | I7: 72654 | J7: 70841 | K7: 69573 | L7: 69529 | M7: 69284 | N7: 68797 | O7: 68254 | P7: 67749 | Q7: 66825 | R7: 65253 | S7: 65158 | T7: 63898 | U7: 62734
C8: Lithuania | D8: 134585 | E8: 132192 | F8: 128384 | G8: 121685 | H8: 116577 | I8: 113491 | J8: 111532 | K8: 109990 | L8: 109489 | M8: 108774 | N8: 107294 | O8: 105221 | P8: 103440 | Q8: 100431 | R8: 97623 | S8: 96817 | T8: =AVERAGE(S8,U8) -> 95800.5 | U8: 94784
A9: 50-54 | B9: males | C9: Estonia | D9: 42940 | E9: 43370 | F9: 43640 | G9: 43770 | H9: 44146 | I9: 44243 | J9: 43966 | K9: 43457 | L9: 41991 | M9: 41056 | N9: 40263 | O9: 40588 | P9: 41120 | Q9: 42241 | R9: 43700 | S9: 45608 | T9: 46318 | U9: 46471
C10: Latvia | D10: 67739 | E10: 69641 | F10: 70320 | G10: 70695 | H10: 71476 | I10: 71159 | J10: 69665 | K10: 68443 | L10: 66203 | M10: 63918 | N10: 62193 | O10: 61191 | P10: 60656 | Q10: 60765 | R10: 61275 | S10: 61077 | T10: 61022 | U10: 61077
C11: Lithuania | D11: 96444 | E11: 101167 | F11: 104849 | G11: 107324 | H11: 110480 | I11: 111567 | J11: 110418 | K11: 108696 | L11: 105685 | M11: 102196 | N11: 99432 | O11: 98319 | P11: 98124 | Q11: 97747 | R11: 98385 | S11: 99331 | T11: 99459 | U11: 97989
A12: 50-54 | B12: females | C12: Estonia | D12: 49670 | E12: 49850 | F12: 49660 | G12: 49420 | H12: 49414 | I12: 48897 | J12: 47982 | K12: 46956 | L12: 45243 | M12: 43622 | N12: 42678 | O12: 42517 | P12: 42693 | Q12: 43296 | R12: 44298 | S12: 46160 | T12: 46811 | U12: 46921
C13: Latvia | D13: 79866 | E13: 81399 | F13: 81909 | G13: 82148 | H13: 82429 | I13: 81831 | J13: 80335 | K13: 78170 | L13: 74667 | M13: 71937 | N13: 69692 | O13: 68068 | P13: 67059 | Q13: 67333 | R13: 67428 | S13: 68256 | T13: 67814 | U13: 67306
C14: Lithuania | D14: 111325 | E14: 116663 | F14: 121351 | G14: 123817 | H14: 126795 | I14: 127573 | J14: 125467 | K14: 122408 | L14: 118032 | M14: 113584 | N14: 110638 | O14: 108951 | P14: 107694 | Q14: 108319 | R14: 107927 | S14: 107604 | T14: 105861 | U14: 104208
A15: 55-59 | B15: males | C15: Estonia | D15: 38920 | E15: 38980 | F15: 38910 | G15: 39600 | H15: 39819 | I15: 40131 | J15: 40624 | K15: 41007 | L15: 40928 | M15: 41279 | N15: 41770 | O15: 41833 | P15: 41599 | Q15: 40735 | R15: 40122 | S15: 39645 | T15: 39939 | U15: 40210
C16: Latvia | D16: 59161 | E16: 58360 | F16: 57936 | G16: 58427 | H16: 58801 | I16: 60457 | J16: 62715 | K16: 63999 | L16: 64872 | M16: 65686 | N16: 65401 | O16: 64246 | P16: 63178 | Q16: 61409 | R16: 59520 | S16: 58253 | T16: 57573 | U16: 57334
C17: Lithuania | D17: 83465 | E17: 83184 | F17: 82608 | G17: 82796 | H17: 83510 | I17: 86305 | J17: 91379 | K17: 95763 | L17: 99361 | M17: 103039 | N17: 104409 | O17: 103817 | P17: 102927 | Q17: 101687 | R17: 98930 | S17: 97036 | T17: 96583 | U17: 95956
A18: 55-59 | B18: females | C18: Estonia | D18: 48640 | E18: 48360 | F18: 48020 | G18: 48500 | H18: 48350 | I18: 48211 | J18: 48340 | K18: 48243 | L18: 47800 | M18: 47827 | N18: 47508 | O18: 46886 | P18: 46041 | Q18: 44831 | R18: 43442 | S18: 43370 | T18: 43454 | U18: 43496
C19: Latvia | D19: 76293 | E19: 75090 | F19: 73921 | G19: 74277 | H19: 74242 | I19: 75098 | J19: 76895 | K19: 77823 | L19: 78509 | M19: 78888 | N19: 78545 | O19: 77162 | P19: 75104 | Q19: 72108 | R19: 69710 | S19: 69061 | T19: 67641 | U19: 66613
C20: Lithuania | D20: 104333 | E20: 103649 | F20: 102307 | G20: 102162 | H20: 102883 | I20: 105307 | J20: 110725 | K20: 115518 | L20: 119526 | M20: 123087 | N20: 123933 | O20: 122205 | P20: 119498 | Q20: 116887 | R20: 113102 | S20: 111014 | T20: 109657 | U20: 108456
A21: 60-64 | B21: males | C21: Estonia | D21: 28060 | E21: 29890 | F21: 32150 | G21: 33870 | H21: 34754 | I21: 35155 | J21: 35311 | K21: 35436 | L21: 36463 | M21: 36759 | N21: 37181 | O21: 37809 | P21: 38391 | Q21: 38599 | R21: 39044 | S21: 39870 | T21: 39987 | U21: 39653
C22: Latvia | D22: 45702 | E22: 46268 | F22: 47838 | G22: 49557 | H22: 51130 | I22: 51510 | J22: 51120 | K22: 51131 | L22: 51956 | M22: 52609 | N22: 54198 | O22: 56322 | P22: 57448 | Q22: 58392 | R22: 59254 | S22: 60076 | T22: 59121 | U22: 58191
C23: Lithuania | D23: 64612 | E23: 64457 | F23: 67388 | G23: 68523 | H23: 70741 | I23: 72884 | J23: 73400 | K23: 73744 | L23: 75059 | M23: 76332 | N23: 79304 | O23: 84215 | P23: 88688 | Q23: 92818 | R23: 96792 | S23: 98908 | T23: 98858 | U23: 97773
A24: 60-64 | B24: females | C24: Estonia | D24: 38040 | E24: 40540 | F24: 43390 | G24: 45650 | H24: 46709 | I24: 47065 | J24: 46821 | K24: 46485 | L24: 47047 | M24: 46886 | N24: 46963 | O24: 47297 | P24: 47345 | Q24: 47240 | R24: 47490 | S24: 47943 | T24: 47496 | U24: 46642
C25: Latvia | D25: 64634 | E25: 65198 | F25: 67670 | G25: 69621 | H25: 71433 | I25: 71864 | J25: 70929 | K25: 70010 | L25: 70529 | M25: 70804 | N25: 71699 | O25: 73417 | P25: 74399 | Q25: 75130 | R25: 75596 | S25: 77172 | T25: 76032 | U25: 74042
C26: Lithuania | D26: 88949 | E26: 88561 | F26: 92845 | G26: 94094 | H26: 96998 | I26: 99310 | J26: 98886 | K26: 97897 | L26: 98450 | M26: 99441 | N26: 101997 | O26: 107456 | P26: 112343 | Q26: 117176 | R26: 121271 | S26: 123329 | T26: 121956 | U26: 119235
A27: 65-69 | B27: males | C27: Estonia | D27: 28700 | E27: 27000 | F27: 25470 | G27: 24340 | H27: 23678 | I27: 24352 | J27: 26084 | K27: 28117 | L27: 29973 | M27: 30840 | N27: 31388 | O27: 31841 | P27: 32108 | Q27: 32965 | R27: 33234 | S27: 33840 | T27: 34651 | U27: 35263
C28: Latvia | D28: 48548 | E28: 46368 | F28: 43586 | G28: 40836 | H28: 38217 | I28: 37821 | J28: 38658 | K28: 40349 | L28: 42187 | M28: 43615 | N28: 44025 | O28: 43780 | P28: 43882 | Q28: 44750 | R28: 45217 | S28: 47707 | T28: 49870 | U28: 51020
C29: Lithuania | D29: 65296 | E29: 63304 | F29: 60052 | G29: 58543 | H29: 55761 | I29: 53639 | J29: 53809 | K29: 56914 | L29: 58399 | M29: 60691 | N29: 62891 | O29: 63663 | P29: 64196 | Q29: 65526 | R29: 66858 | S29: 70598 | T29: 75526 | U29: 79928
A30: 65-69 | B30: females | C30: Estonia | D30: 44410 | E30: 41470 | F30: 38750 | G30: 36630 | H30: 35264 | I30: 36027 | J30: 38537 | K30: 41358 | L30: 43836 | M30: 45011 | N30: 45543 | O30: 45503 | P30: 45393 | Q30: 45966 | R30: 45831 | S30: 46586 | T30: 47246 | U30: 47537
C31: Latvia | D31: 77807 | E31: 74373 | F31: 70263 | G31: 65686 | H31: 61632 | I31: 59991 | J31: 60593 | K31: 63150 | L31: 65230 | M31: 67017 | N31: 67530 | O31: 66689 | P31: 65922 | Q31: 66714 | R31: 67036 | S31: 69235 | T31: 70940 | U31: 71983
C32: Lithuania | D32: 99741 | E32: 97256 | F32: 92833 | G32: 90956 | H32: 86920 | I32: 83379 | J32: 83190 | K32: 87528 | L32: 88908 | M32: 91781 | N32: 94036 | O32: 93827 | P32: 92907 | Q32: 93500 | R32: 94867 | S32: 98613 | T32: 104603 | U32: 110028
A33: 70-74 | B33: males | C33: Estonia | D33: 21630 | E33: 22320 | F33: 23200 | G33: 23390 | H33: 24021 | I33: 23498 | J33: 22243 | K33: 21058 | L33: 20131 | M33: 19800 | N33: 20531 | O33: 21967 | P33: 23816 | Q33: 25319 | R33: 25969 | S33: 26447 | T33: 26914 | U33: 27338
C34: Latvia | D34: 34702 | E34: 36065 | F34: 37704 | G34: 38268 | H34: 38856 | I34: 37981 | J34: 36487 | K34: 34418 | L34: 32326 | M34: 30274 | N34: 30195 | O34: 31002 | P34: 32666 | Q34: 34143 | R34: 34981 | S34: 35595 | T34: 35602 | U34: 35896
C35: Lithuania | D35: 52723 | E35: 52865 | F35: 53156 | G35: 52750 | H35: 52158 | I35: 52154 | J35: 50608 | K35: 48056 | L35: 46884 | M35: 44703 | N35: 43144 | O35: 43507 | P35: 46407 | Q35: 49426 | R35: 50894 | S35: 52532 | T35: 53345 | U35: 54065
A36: 70-74 | B36: females | C36: Estonia | D36: 38960 | E36: 40330 | F36: 41820 | G36: 42030 | H36: 42839 | I36: 41190 | J36: 38477 | K36: 35970 | L36: 34117 | M36: 32962 | N36: 33746 | O36: 36137 | P36: 38893 | Q36: 41100 | R36: 42148 | S36: 43025 | T36: 43285 | U36: 43337
C37: Latvia | D37: 65291 | E37: 67258 | F37: 69853 | G37: 71052 | H37: 71606 | I37: 70188 | J37: 67202 | K37: 63605 | L37: 59545 | M37: 55967 | N37: 54535 | O37: 55230 | P37: 57704 | Q37: 59652 | R37: 61032 | S37: 62135 | T37: 61554 | U37: 61070
C38: Lithuania | D38: 92932 | E38: 93178 | F38: 93267 | G38: 92465 | H38: 91379 | I38: 90983 | J38: 88836 | K38: 84785 | L38: 83112 | M38: 79406 | N38: 76190 | O38: 76246 | P38: 80455 | Q38: 82581 | R38: 85010 | S38: 87559 | T38: 87612 | U38: 87127
A39: 75-79 | B39: males | C39: Estonia | D39: 15920 | E39: 15670 | F39: 15390 | G39: 15300 | H39: 15572 | I39: 16123 | J39: 16775 | K39: 17613 | L39: 17867 | M39: 18367 | N39: 18058 | O39: 17256 | P39: 16407 | Q39: 15674 | R39: 15306 | S39: 16062 | T39: 17216 | U39: 18748
C40: Latvia | D40: 25213 | E40: 24653 | F40: 23844 | G40: 23504 | H40: 23734 | I40: 24701 | J40: 25937 | K40: 27367 | L40: 27979 | M40: 28599 | N40: 27829 | O40: 26728 | P40: 25191 | Q40: 23578 | R40: 21970 | S40: 22089 | T40: 22907 | U40: 24219
...

Sheet Disability
A1: Percentage of Disabled per Age and Gender group 2008-2025 (annual) | E1: 2008 | F1: 2009 | G1: 2010 | H1: 2011 | I1: 2012 | J1: 2013 | K1: 2014 | L1: 2015 | M1: 2016 | N1: 2017 | O1: 2018 | P1: 2019 | Q1: 2020 | R1: 2021 | S1: 2022 | T1: 2023 | U1: 2024 | V1: 2025 | W1: 2026 | X1: 2027 | Y1: 2028 | Z1: 2029 | AA1: 2030 | AB1: 2031 | AC1: 2032 | AD1: 2033 | AE1: 2034 | AF1: 2035 | AG1: 2036
A2: Age group | B2: Gender | C2: Disability | D2: Country
A3: 45-54 | B3: males | C3: some or severe | D3: Estonia | E3: 29 | F3: 28.4 | G3: 31.2 | H3: 32.2 | I3: 30.1 | J3: 32 | K3: 32.6 | L3: 31.8 | M3: 26.6 | N3: 30 | O3: 33.8 | P3: 29.9 | Q3: 28.3 | R3: 26 | S3: 24.7 | T3: 28.1 | U3: 28.1 | V3: 29.6
D4: Latvia | E4: 31.5 | F4: 29.3 | G4: 27.9 | H4: 27.4 | I4: 25.4 | J4: 33.7 | K4: 37.1 | L4: 35.2 | M4: 35.2 | N4: 39.3 | O4: 36.7 | P4: 35.6 | Q4: 34 | R4: 29.2 | S4: 31.6 | T4: 32.1 | U4: 36.4 | V4: 26.5
D5: Lithuania | E5: 18.6 | F5: 14.4 | G5: 14.2 | H5: 16.5 | I5: 19 | J5: 18.4 | K5: 17.1 | L5: 21.2 | M5: 21.7 | N5: 21.5 | O5: 22.9 | P5: 21.5 | Q5: 26.4 | R5: 22.7 | S5: 20.9 | T5: 23 | U5: 16.8 | V5: 16.6
A6: 45-54 | B6: males | C6: none | D6: Estonia | E6: 71 | F6: 71.6 | G6: 68.8 | H6: 67.8 | I6: 69.9 | J6: 68 | K6: 67.4 | L6: 68.2 | M6: 73.4 | N6: 70 | O6: 66.2 | P6: 70.1 | Q6: 71.7 | R6: 74 | S6: 75.3 | T6: 71.9 | U6: 71.9 | V6: 70.4
D7: Latvia | E7: 68.5 | F7: 70.7 | G7: 72.1 | H7: 72.6 | I7: 74.6 | J7: 66.3 | K7: 62.9 | L7: 64.8 | M7: 64.8 | N7: 60.7 | O7: 63.3 | P7: 64.4 | Q7: 66 | R7: 70.8 | S7: 68.4 | T7: 67.9 | U7: 63.6 | V7: 73.5
D8: Lithuania | E8: 81.4 | F8: 85.6 | G8: 85.8 | H8: 83.5 | I8: 81 | J8: 81.6 | K8: 82.9 | L8: 78.8 | M8: 78.3 | N8: 78.5 | O8: 77.1 | P8: 78.5 | Q8: 73.6 | R8: 77.3 | S8: 79.1 | T8: 77 | U8: 83.2 | V8: 83.4
A9: 45-54 | B9: females | C9: some or severe | D9: Estonia | E9: 23 | F9: 24.8 | G9: 28.2 | H9: 30.3 | I9: 29 | J9: 28.6 | K9: 28.4 | L9: 28.4 | M9: 26 | N9: 26 | O9: 32.9 | P9: 27 | Q9: 25.1 | R9: 27 | S9: 22.2 | T9: 29.1 | U9: 26.7 | V9: 28.6
D10: Latvia | E10: 32.4 | F10: 28.8 | G10: 26.4 | H10: 28.7 | I10: 27.1 | J10: 35.1 | K10: 35.9 | L10: 34.9 | M10: 34.5 | N10: 39 | O10: 36.9 | P10: 37.8 | Q10: 35.3 | R10: 29.3 | S10: 30.3 | T10: 37.5 | U10: 33.2 | V10: 29.6
D11: Lithuania | E11: 20.7 | F11: 19.4 | G11: 15.8 | H11: 19.2 | I11: 17.5 | J11: 17.4 | K11: 16.5 | L11: 20.9 | M11: 21.5 | N11: 20.7 | O11: 22.6 | P11: 21.5 | Q11: 24.1 | R11: 24.1 | S11: 17.8 | T11: 16.2 | U11: 12.5 | V11: 11.4
A12: 45-54 | B12: females | C12: none | D12: Estonia | E12: 77 | F12: 75.2 | G12: 71.8 | H12: 69.7 | I12: 71 | J12: 71.4 | K12: 71.6 | L12: 71.6 | M12: 74 | N12: 74 | O12: 67.1 | P12: 73 | Q12: 74.9 | R12: 73 | S12: 77.8 | T12: 70.9 | U12: 73.3 | V12: 71.4
D13: Latvia | E13: 67.6 | F13: 71.2 | G13: 73.6 | H13: 71.3 | I13: 72.9 | J13: 64.9 | K13: 64.1 | L13: 65.1 | M13: 65.5 | N13: 61 | O13: 63.1 | P13: 62.2 | Q13: 64.7 | R13: 70.7 | S13: 69.7 | T13: 62.5 | U13: 66.8 | V13: 70.4
D14: Lithuania | E14: 79.3 | F14: 80.6 | G14: 84.2 | H14: 80.8 | I14: 82.5 | J14: 82.6 | K14: 83.5 | L14: 79.1 | M14: 78.5 | N14: 79.3 | O14: 77.4 | P14: 78.5 | Q14: 75.9 | R14: 75.9 | S14: 82.2 | T14: 83.8 | U14: 87.5 | V14: 88.6
A15: 55-64 | B15: males | C15: some or severe | D15: Estonia | E15: 45.9 | F15: 37.6 | G15: 43 | H15: 46.6 | I15: 49.5 | J15: 46.4 | K15: 47.6 | L15: 47.8 | M15: 45.9 | N15: 46.2 | O15: 50.2 | P15: 45.1 | Q15: 40.2 | R15: 41.5 | S15: 41.8 | T15: 43.1 | U15: 42.7 | V15: 43.8
D16: Latvia | E16: 46 | F16: 45.2 | G16: 42.1 | H16: 42.1 | I16: 35.2 | J16: 42.9 | K16: 49.5 | L16: 46.8 | M16: 48 | N16: 53.7 | O16: 49.4 | P16: 50.1 | Q16: 50.8 | R16: 45.2 | S16: 44.8 | T16: 49.1 | U16: 52.2 | V16: 44.2
D17: Lithuania | E17: 40.1 | F17: 32.8 | G17: 32.7 | H17: 33.2 | I17: 35.9 | J17: 35.1 | K17: 32.7 | L17: 40.3 | M17: 38.8 | N17: 38.3 | O17: 35 | P17: 36.8 | Q17: 39.2 | R17: 38 | S17: 32.8 | T17: 33.5 | U17: 29.5 | V17: 28.9
A18: 55-64 | B18: males | C18: none | D18: Estonia | E18: 54.1 | F18: 62.4 | G18: 57 | H18: 53.4 | I18: 50.5 | J18: 53.6 | K18: 52.4 | L18: 52.2 | M18: 54.1 | N18: 53.8 | O18: 49.8 | P18: 54.9 | Q18: 59.8 | R18: 58.5 | S18: 58.2 | T18: 56.9 | U18: 57.3 | V18: 56.2
D19: Latvia | E19: 54 | F19: 54.8 | G19: 57.9 | H19: 57.9 | I19: 64.8 | J19: 57.1 | K19: 50.5 | L19: 53.2 | M19: 52 | N19: 46.3 | O19: 50.6 | P19: 49.9 | Q19: 49.2 | R19: 54.8 | S19: 55.2 | T19: 50.9 | U19: 47.8 | V19: 55.8
D20: Lithuania | E20: 59.9 | F20: 67.2 | G20: 67.3 | H20: 66.8 | I20: 64.1 | J20: 64.9 | K20: 67.3 | L20: 59.7 | M20: 61.2 | N20: 61.7 | O20: 65 | P20: 63.2 | Q20: 60.8 | R20: 62 | S20: 67.2 | T20: 66.5 | U20: 70.5 | V20: 71.1
A21: 55-64 | B21: females | C21: some or severe | D21: Estonia | E21: 44.2 | F21: 38.5 | G21: 38.4 | H21: 41.8 | I21: 48.3 | J21: 46.6 | K21: 47.1 | L21: 47.2 | M21: 39.6 | N21: 44.7 | O21: 47 | P21: 44.1 | Q21: 43.5 | R21: 42.5 | S21: 37.2 | T21: 43 | U21: 34.2 | V21: 38
D22: Latvia | E22: 52.1 | F22: 48.9 | G22: 47.2 | H22: 46.3 | I22: 38.5 | J22: 52.2 | K22: 50.5 | L22: 52.3 | M22: 48.8 | N22: 53.1 | O22: 51.1 | P22: 50.3 | Q22: 52 | R22: 47.2 | S22: 49.6 | T22: 47.9 | U22: 49.8 | V22: 42.7
D23: Lithuania | E23: 41.7 | F23: 37.1 | G23: 32.8 | H23: 32.8 | I23: 34.3 | J23: 34.6 | K23: 33 | L23: 40.2 | M23: 38.3 | N23: 35.7 | O23: 36.2 | P23: 38.9 | Q23: 39.4 | R23: 37.9 | S23: 34.9 | T23: 31.5 | U23: 25.9 | V23: 26.8
A24: 55-64 | B24: females | C24: none | D24: Estonia | E24: 55.8 | F24: 61.5 | G24: 61.6 | H24: 58.2 | I24: 51.7 | J24: 53.4 | K24: 52.9 | L24: 52.8 | M24: 60.4 | N24: 55.3 | O24: 53 | P24: 55.9 | Q24: 56.5 | R24: 57.5 | S24: 62.8 | T24: 57 | U24: 65.8 | V24: 62
D25: Latvia | E25: 47.9 | F25: 51.1 | G25: 52.8 | H25: 53.7 | I25: 61.5 | J25: 47.8 | K25: 49.5 | L25: 47.7 | M25: 51.2 | N25: 46.9 | O25: 48.9 | P25: 49.7 | Q25: 48 | R25: 52.8 | S25: 50.4 | T25: 52.1 | U25: 50.2 | V25: 57.3
D26: Lithuania | E26: 58.3 | F26: 62.9 | G26: 67.2 | H26: 67.2 | I26: 65.7 | J26: 65.4 | K26: 67 | L26: 59.8 | M26: 61.7 | N26: 64.3 | O26: 63.8 | P26: 61.1 | Q26: 60.6 | R26: 62.1 | S26: 65.1 | T26: 68.5 | U26: 74.1 | V26: 73.2
A27: 65-74 | B27: males | C27: some or severe | D27: Estonia | E27: 64.1 | F27: 52.1 | G27: 59.1 | H27: 57 | I27: 59.3 | J27: 62 | K27: 59.3 | L27: 62 | M27: 56.5 | N27: 57.2 | O27: 55.8 | P27: 53.4 | Q27: 56 | R27: 52.4 | S27: 49.3 | T27: 52.7 | U27: 52.1 | V27: 52.3
D28: Latvia | E28: 56.7 | F28: 60 | G28: 57.4 | H28: 58.8 | I28: 56.8 | J28: 66.6 | K28: 64.1 | L28: 63.8 | M28: 60 | N28: 62.4 | O28: 63.7 | P28: 64.7 | Q28: 63.1 | R28: 59.5 | S28: 61.6 | T28: 61.1 | U28: 66.7 | V28: 55.9
D29: Lithuania | E29: 49.4 | F29: 48.8 | G29: 44.8 | H29: 49 | I29: 52.1 | J29: 49.2 | K29: 49 | L29: 56.3 | M29: 50.5 | N29: 53.6 | O29: 54.9 | P29: 49.6 | Q29: 51.2 | R29: 56.1 | S29: 49.3 | T29: 46.1 | U29: 36.1 | V29: 36.3
A30: 65-74 | B30: males | C30: none | D30: Estonia | E30: 35.9 | F30: 47.9 | G30: 40.9 | H30: 43 | I30: 40.7 | J30: 38 | K30: 40.7 | L30: 38 | M30: 43.5 | N30: 42.8 | O30: 44.2 | P30: 46.6 | Q30: 44 | R30: 47.6 | S30: 50.7 | T30: 47.3 | U30: 47.9 | V30: 47.7
D31: Latvia | E31: 43.3 | F31: 40 | G31: 42.6 | H31: 41.2 | I31: 43.2 | J31: 33.4 | K31: 35.9 | L31: 36.2 | M31: 40 | N31: 37.6 | O31: 36.3 | P31: 35.3 | Q31: 36.9 | R31: 40.5 | S31: 38.4 | T31: 38.9 | U31: 33.3 | V31: 44.1
D32: Lithuania | E32: 50.6 | F32: 51.2 | G32: 55.2 | H32: 51 | I32: 47.9 | J32: 50.8 | K32: 51 | L32: 43.7 | M32: 49.5 | N32: 46.4 | O32: 45.1 | P32: 50.4 | Q32: 48.8 | R32: 43.9 | S32: 50.7 | T32: 53.9 | U32: 63.9 | V32: 63.7
A33: 65-74 | B33: females | C33: some or severe | D33: Estonia | E33: 66.7 | F33: 61.3 | G33: 61.7 | H33: 61.8 | I33: 63 | J33: 60.7 | K33: 60.4 | L33: 64.6 | M33: 54.2 | N33: 57.7 | O33: 62.4 | P33: 55.3 | Q33: 51.2 | R33: 51 | S33: 49.2 | T33: 49.7 | U33: 49.9 | V33: 49.7
D34: Latvia | E34: 64.2 | F34: 60.7 | G34: 61.3 | H34: 65.1 | I34: 57 | J34: 71.4 | K34: 67.6 | L34: 70.9 | M34: 68.3 | N34: 69.1 | O34: 65.6 | P34: 65.9 | Q34: 66.3 | R34: 62.1 | S34: 64.2 | T34: 64.1 | U34: 66.3 | V34: 57.8
D35: Lithuania | E35: 59.9 | F35: 54 | G35: 54.3 | H35: 55 | I35: 58.6 | J35: 54.5 | K35: 59 | L35: 60.2 | M35: 58.6 | N35: 61.8 | O35: 58.5 | P35: 56.5 | Q35: 55.2 | R35: 52.1 | S35: 45.6 | T35: 44.8 | U35: 38.3 | V35: 38.6
A36: 65-74 | B36: females | C36: none | D36: Estonia | E36: 33.3 | F36: 38.7 | G36: 38.3 | H36: 38.2 | I36: 37 | J36: 39.3 | K36: 39.6 | L36: 35.4 | M36: 45.8 | N36: 42.3 | O36: 37.6 | P36: 44.7 | Q36: 48.8 | R36: 49 | S36: 50.8 | T36: 50.3 | U36: 50.1 | V36: 50.3
D37: Latvia | E37: 35.8 | F37: 39.3 | G37: 38.7 | H37: 34.9 | I37: 43 | J37: 28.6 | K37: 32.4 | L37: 29.1 | M37: 31.7 | N37: 30.9 | O37: 34.4 | P37: 34.1 | Q37: 33.7 | R37: 37.9 | S37: 35.8 | T37: 35.9 | U37: 33.7 | V37: 42.2
D38: Lithuania | E38: 40.1 | F38: 46 | G38: 45.7 | H38: 45 | I38: 41.4 | J38: 45.5 | K38: 41 | L38: 39.8 | M38: 41.4 | N38: 38.2 | O38: 41.5 | P38: 43.5 | Q38: 44.8 | R38: 47.9 | S38: 54.4 | T38: 55.2 | U38: 61.7 | V38: 61.4
A39: 75-84 | B39: males | C39: some or severe | D39: Estonia | E39: 81.8 | F39: 72.3 | G39: 66.8 | H39: 67.7 | I39: 66.3 | J39: 70.1 | K39: 76.5 | L39: 68.9 | M39: 73.3 | N39: 67.3 | O39: 69.4 | P39: 65.9 | Q39: 65.5 | R39: 63.8 | S39: 57.4 | T39: 61.6 | U39: 53.4 | V39: 66
D40: Latvia | E40: 70.9 | F40: 74.3 | G40: 72.7 | H40: 76.9 | I40: 68.2 | J40: 79.3 | K40: 80.2 | L40: 80.7 | M40: 79.8 | N40: 80.3 | O40: 79.8 | P40: 71.3 | Q40: 80.9 | R40: 76.7 | S40: 81.9 | T40: 76 | U40: 81.5 | V40: 73.2
...

Sheet Income
A1: Mean Equivalised Income as Purchasing Power Standard per Age and Gender Group 2008-2025 (annual) | D1: 2008 | E1: 2009 | F1: 2010 | G1: 2011 | H1: 2012 | I1: 2013 | J1: 2014 | K1: 2015 | L1: 2016 | M1: 2017 | N1: 2018 | O1: 2019 | P1: 2020 | Q1: 2021 | R1: 2022 | S1: 2023 | T1: 2024 | U1: 2025 | V1: 2026 | W1: 2027 | X1: 2028 | Y1: 2029 | Z1: 2030 | AA1: 2031 | AB1: 2032 | AC1: 2033 | AD1: 2034 | AE1: 2035 | AF1: 2036
A2: Age group | B2: Gender | C2: Country
A3: 25-54 | B3: males | C3: Estonia | D3: 9937 | E3: 10637 | F3: 9883 | G3: 9693 | H3: 10658 | I3: 11815 | J3: 12910 | K3: 14189 | L3: 15671 | M3: 15656 | N3: 16484 | O3: 17598 | P3: 17732 | Q3: 18834 | R3: 21974 | S3: 20043 | T3: 20972 | U3: 21874 | V3: =_xlfn.FORECAST.LINEAR(V$1,$D3:U3,$D$1:U$1) -> 22917.758 | W3: =_xlfn.FORECAST.LINEAR(W$1,$D3:V3,$D$1:V$1) -> 23712.844 | X3: =_xlfn.FORECAST.LINEAR(X$1,$D3:W3,$D$1:W$1) -> 24507.929 | Y3: =_xlfn.FORECAST.LINEAR(Y$1,$D3:X3,$D$1:X$1) -> 25303.015 | Z3: =_xlfn.FORECAST.LINEAR(Z$1,$D3:Y3,$D$1:Y$1) -> 26098.101 | AA3: =_xlfn.FORECAST.LINEAR(AA$1,$D3:Z3,$D$1:Z$1)*AVERAGE($L45:P45) -> 28089.525 | AB3: =_xlfn.FORECAST.LINEAR(AB$1,$D3:AA3,$D$1:AA$1)*AVERAGE($L45:Q45) -> 28976.119 | AC3: =_xlfn.FORECAST.LINEAR(AC$1,$D3:AB3,$D$1:AB$1)*AVERAGE($L45:R45) -> 30372.856 | AD3: =_xlfn.FORECAST.LINEAR(AD$1,$D3:AC3,$D$1:AC$1)*AVERAGE($L45:S45) -> 31131.259 | AE3: =_xlfn.FORECAST.LINEAR(AE$1,$D3:AD3,$D$1:AD$1)*AVERAGE($L45:T45) -> 31958.204 | AF3: =_xlfn.FORECAST.LINEAR(AF$1,$D3:AE3,$D$1:AE$1)*AVERAGE($L45:U45) -> 32826.613
C4: Latvia | D4: 9920 | E4: 9622 | F4: 7783 | G4: 7838 | H4: 8135 | I4: 8808 | J4: 9894 | K4: 11084 | L4: 12420 | M4: 12485 | N4: 13674 | O4: 15012 | P4: 15087 | Q4: 16660 | R4: 17489 | S4: 17764 | T4: 19983 | U4: 23673 | V4: =_xlfn.FORECAST.LINEAR(V$1,$D4:U4,$D$1:U$1) -> 20824.595 | W4: =_xlfn.FORECAST.LINEAR(W$1,$D4:V4,$D$1:V$1) -> 21628.757 | X4: =_xlfn.FORECAST.LINEAR(X$1,$D4:W4,$D$1:W$1) -> 22432.919 | Y4: =_xlfn.FORECAST.LINEAR(Y$1,$D4:X4,$D$1:X$1) -> 23237.081 | Z4: =_xlfn.FORECAST.LINEAR(Z$1,$D4:Y4,$D$1:Y$1) -> 24041.243 | AA4: =_xlfn.FORECAST.LINEAR(AA$1,$D4:Z4,$D$1:Z$1)*AVERAGE($L46:P46) -> 28548.356 | AB4: =_xlfn.FORECAST.LINEAR(AB$1,$D4:AA4,$D$1:AA$1)*AVERAGE($L46:Q46) -> 30015.678 | AC4: =_xlfn.FORECAST.LINEAR(AC$1,$D4:AB4,$D$1:AB$1)*AVERAGE($L46:R46) -> 31451.343 | AD4: =_xlfn.FORECAST.LINEAR(AD$1,$D4:AC4,$D$1:AC$1)*AVERAGE($L46:S46) -> 32755.369 | AE4: =_xlfn.FORECAST.LINEAR(AE$1,$D4:AD4,$D$1:AD$1)*AVERAGE($L46:T46) -> 34347.855 | AF4: =_xlfn.FORECAST.LINEAR(AF$1,$D4:AE4,$D$1:AE$1)*AVERAGE($L46:U46) -> 36378.993
C5: Lithuania | D5: 9331 | E5: 9818 | F5: 7764 | G5: 7530 | H5: 8706 | I5: 9504 | J5: 10463 | K5: 11850 | L5: 13561 | M5: 14608 | N5: 15412 | O5: 15844 | P5: 17565 | Q5: 19806 | R5: 21111 | S5: 20925 | T5: 22128 | U5: 25784 | V5: =_xlfn.FORECAST.LINEAR(V$1,$D5:U5,$D$1:U$1) -> 24145.327 | W5: =_xlfn.FORECAST.LINEAR(W$1,$D5:V5,$D$1:V$1) -> 25156.472 | X5: =_xlfn.FORECAST.LINEAR(X$1,$D5:W5,$D$1:W$1) -> 26167.618 | Y5: =_xlfn.FORECAST.LINEAR(Y$1,$D5:X5,$D$1:X$1) -> 27178.763 | Z5: =_xlfn.FORECAST.LINEAR(Z$1,$D5:Y5,$D$1:Y$1) -> 28189.909 | AA5: =_xlfn.FORECAST.LINEAR(AA$1,$D5:Z5,$D$1:Z$1)*AVERAGE($L47:P47) -> 33335.214 | AB5: =_xlfn.FORECAST.LINEAR(AB$1,$D5:AA5,$D$1:AA$1)*AVERAGE($L47:Q47) -> 35325.564 | AC5: =_xlfn.FORECAST.LINEAR(AC$1,$D5:AB5,$D$1:AB$1)*AVERAGE($L47:R47) -> 37261.373 | AD5: =_xlfn.FORECAST.LINEAR(AD$1,$D5:AC5,$D$1:AC$1)*AVERAGE($L47:S47) -> 38856.933 | AE5: =_xlfn.FORECAST.LINEAR(AE$1,$D5:AD5,$D$1:AD$1)*AVERAGE($L47:T47) -> 40505.806 | AF5: =_xlfn.FORECAST.LINEAR(AF$1,$D5:AE5,$D$1:AE$1)*AVERAGE($L47:U47) -> 42607.942
A6: 25-54 | B6: females | C6: Estonia | D6: 9633 | E6: 10410 | F6: 9539 | G6: 9509 | H6: 10334 | I6: 11388 | J6: 12789 | K6: 14201 | L6: 15542 | M6: 16001 | N6: 17052 | O6: 18058 | P6: 18252 | Q6: 18874 | R6: 22581 | S6: 19760 | T6: 20755 | U6: 21756 | V6: =_xlfn.FORECAST.LINEAR(V$1,$D6:U6,$D$1:U$1) -> 23182.895 | W6: =_xlfn.FORECAST.LINEAR(W$1,$D6:V6,$D$1:V$1) -> 24006.627 | X6: =_xlfn.FORECAST.LINEAR(X$1,$D6:W6,$D$1:W$1) -> 24830.359 | Y6: =_xlfn.FORECAST.LINEAR(Y$1,$D6:X6,$D$1:X$1) -> 25654.09 | Z6: =_xlfn.FORECAST.LINEAR(Z$1,$D6:Y6,$D$1:Y$1) -> 26477.822 | AA6: =_xlfn.FORECAST.LINEAR(AA$1,$D6:Z6,$D$1:Z$1)*AVERAGE($L48:P48) -> 28891.45 | AB6: =_xlfn.FORECAST.LINEAR(AB$1,$D6:AA6,$D$1:AA$1)*AVERAGE($L48:Q48) -> 29697.694 | AC6: =_xlfn.FORECAST.LINEAR(AC$1,$D6:AB6,$D$1:AB$1)*AVERAGE($L48:R48) -> 31163.788 | AD6: =_xlfn.FORECAST.LINEAR(AD$1,$D6:AC6,$D$1:AC$1)*AVERAGE($L48:S48) -> 31820.268 | AE6: =_xlfn.FORECAST.LINEAR(AE$1,$D6:AD6,$D$1:AD$1)*AVERAGE($L48:T48) -> 32583.944 | AF6: =_xlfn.FORECAST.LINEAR(AF$1,$D6:AE6,$D$1:AE$1)*AVERAGE($L48:U48) -> 33420.434
C7: Latvia | D7: 9724 | E7: 9657 | F7: 7811 | G7: 7718 | H7: 7950 | I7: 8435 | J7: 9669 | K7: 10674 | L7: 12275 | M7: 12366 | N7: 13453 | O7: 15024 | P7: 14987 | Q7: 15714 | R7: 16615 | S7: 17076 | T7: 19040 | U7: 22871 | V7: =_xlfn.FORECAST.LINEAR(V$1,$D7:U7,$D$1:U$1) -> 20027.778 | W7: =_xlfn.FORECAST.LINEAR(W$1,$D7:V7,$D$1:V$1) -> 20784.743 | X7: =_xlfn.FORECAST.LINEAR(X$1,$D7:W7,$D$1:W$1) -> 21541.708 | Y7: =_xlfn.FORECAST.LINEAR(Y$1,$D7:X7,$D$1:X$1) -> 22298.673 | Z7: =_xlfn.FORECAST.LINEAR(Z$1,$D7:Y7,$D$1:Y$1) -> 23055.637 | AA7: =_xlfn.FORECAST.LINEAR(AA$1,$D7:Z7,$D$1:Z$1)*AVERAGE($L49:P49) -> 27858.107 | AB7: =_xlfn.FORECAST.LINEAR(AB$1,$D7:AA7,$D$1:AA$1)*AVERAGE($L49:Q49) -> 29071.728 | AC7: =_xlfn.FORECAST.LINEAR(AC$1,$D7:AB7,$D$1:AB$1)*AVERAGE($L49:R49) -> 30351.185 | AD7: =_xlfn.FORECAST.LINEAR(AD$1,$D7:AC7,$D$1:AC$1)*AVERAGE($L49:S49) -> 31578.999 | AE7: =_xlfn.FORECAST.LINEAR(AE$1,$D7:AD7,$D$1:AD$1)*AVERAGE($L49:T49) -> 33059.934 | AF7: =_xlfn.FORECAST.LINEAR(AF$1,$D7:AE7,$D$1:AE$1)*AVERAGE($L49:U49) -> 35024.48
C8: Lithuania | D8: 8908 | E8: 9606 | F8: 7926 | G8: 7630 | H8: 8722 | I8: 9561 | J8: 10322 | K8: 11809 | L8: 12962 | M8: 13386 | N8: 14518 | O8: 15638 | P8: 17013 | Q8: 18631 | R8: 19811 | S8: 19853 | T8: 20598 | U8: 23015 | V8: =_xlfn.FORECAST.LINEAR(V$1,$D8:U8,$D$1:U$1) -> 22415.373 | W8: =_xlfn.FORECAST.LINEAR(W$1,$D8:V8,$D$1:V$1) -> 23313.429 | X8: =_xlfn.FORECAST.LINEAR(X$1,$D8:W8,$D$1:W$1) -> 24211.486 | Y8: =_xlfn.FORECAST.LINEAR(Y$1,$D8:X8,$D$1:X$1) -> 25109.543 | Z8: =_xlfn.FORECAST.LINEAR(Z$1,$D8:Y8,$D$1:Y$1) -> 26007.6 | AA8: =_xlfn.FORECAST.LINEAR(AA$1,$D8:Z8,$D$1:Z$1)*AVERAGE($L50:P50) -> 30150.333 | AB8: =_xlfn.FORECAST.LINEAR(AB$1,$D8:AA8,$D$1:AA$1)*AVERAGE($L50:Q50) -> 31801.169 | AC8: =_xlfn.FORECAST.LINEAR(AC$1,$D8:AB8,$D$1:AB$1)*AVERAGE($L50:R50) -> 33415.528 | AD8: =_xlfn.FORECAST.LINEAR(AD$1,$D8:AC8,$D$1:AC$1)*AVERAGE($L50:S50) -> 34782.19 | AE8: =_xlfn.FORECAST.LINEAR(AE$1,$D8:AD8,$D$1:AD$1)*AVERAGE($L50:T50) -> 36125.625 | AF8: =_xlfn.FORECAST.LINEAR(AF$1,$D8:AE8,$D$1:AE$1)*AVERAGE($L50:U50) -> 37726.405
A9: 55-64 | B9: males | C9: Estonia | D9: 8565 | E9: 9280 | F9: 8556 | G9: 8502 | H9: 8757 | I9: 9482 | J9: 10390 | K9: 12502 | L9: 14168 | M9: 14510 | N9: 15515 | O9: 15942 | P9: 16318 | Q9: 16470 | R9: 19160 | S9: 17404 | T9: 18835 | U9: 19448 | V9: =_xlfn.FORECAST.LINEAR(V$1,$D9:U9,$D$1:U$1) -> 20554.549 | W9: =_xlfn.FORECAST.LINEAR(W$1,$D9:V9,$D$1:V$1) -> 21292.431 | X9: =_xlfn.FORECAST.LINEAR(X$1,$D9:W9,$D$1:W$1) -> 22030.314 | Y9: =_xlfn.FORECAST.LINEAR(Y$1,$D9:X9,$D$1:X$1) -> 22768.196 | Z9: =_xlfn.FORECAST.LINEAR(Z$1,$D9:Y9,$D$1:Y$1) -> 23506.078 | AA9: =_xlfn.FORECAST.LINEAR(AA$1,$D9:Z9,$D$1:Z$1)*AVERAGE($L51:P51) -> 26516.057 | AB9: =_xlfn.FORECAST.LINEAR(AB$1,$D9:AA9,$D$1:AA$1)*AVERAGE($L51:Q51) -> 27186.298 | AC9: =_xlfn.FORECAST.LINEAR(AC$1,$D9:AB9,$D$1:AB$1)*AVERAGE($L51:R51) -> 28358.1 | AD9: =_xlfn.FORECAST.LINEAR(AD$1,$D9:AC9,$D$1:AC$1)*AVERAGE($L51:S51) -> 29001.412 | AE9: =_xlfn.FORECAST.LINEAR(AE$1,$D9:AD9,$D$1:AD$1)*AVERAGE($L51:T51) -> 29831.905 | AF9: =_xlfn.FORECAST.LINEAR(AF$1,$D9:AE9,$D$1:AE$1)*AVERAGE($L51:U51) -> 30667.637
C10: Latvia | D10: 8904 | E10: 8989 | F10: 7353 | G10: 7238 | H10: 7845 | I10: 8126 | J10: 9083 | K10: 9721 | L10: 10936 | M10: 10657 | N10: 11914 | O10: 12441 | P10: 13023 | Q10: 13819 | R10: 15073 | S10: 15012 | T10: 17081 | U10: 20401 | V10: =_xlfn.FORECAST.LINEAR(V$1,$D10:U10,$D$1:U$1) -> 17551.046 | W10: =_xlfn.FORECAST.LINEAR(W$1,$D10:V10,$D$1:V$1) -> 18184.396 | X10: =_xlfn.FORECAST.LINEAR(X$1,$D10:W10,$D$1:W$1) -> 18817.745 | Y10: =_xlfn.FORECAST.LINEAR(Y$1,$D10:X10,$D$1:X$1) -> 19451.095 | Z10: =_xlfn.FORECAST.LINEAR(Z$1,$D10:Y10,$D$1:Y$1) -> 20084.445 | AA10: =_xlfn.FORECAST.LINEAR(AA$1,$D10:Z10,$D$1:Z$1)*AVERAGE($L52:P52) -> 23338.016 | AB10: =_xlfn.FORECAST.LINEAR(AB$1,$D10:AA10,$D$1:AA$1)*AVERAGE($L52:Q52) -> 24397.981 | AC10: =_xlfn.FORECAST.LINEAR(AC$1,$D10:AB10,$D$1:AB$1)*AVERAGE($L52:R52) -> 25603.309 | AD10: =_xlfn.FORECAST.LINEAR(AD$1,$D10:AC10,$D$1:AC$1)*AVERAGE($L52:S52) -> 26619.025 | AE10: =_xlfn.FORECAST.LINEAR(AE$1,$D10:AD10,$D$1:AD$1)*AVERAGE($L52:T52) -> 27914.361 | AF10: =_xlfn.FORECAST.LINEAR(AF$1,$D10:AE10,$D$1:AE$1)*AVERAGE($L52:U52) -> 29596.568
C11: Lithuania | D11: 8228 | E11: 9040 | F11: 8069 | G11: 7725 | H11: 8755 | I11: 9528 | J11: 9959 | K11: 10544 | L11: 12023 | M11: 12571 | N11: 13717 | O11: 15135 | P11: 16424 | Q11: 17659 | R11: 16901 | S11: 17825 | T11: 16485 | U11: 16426 | V11: =_xlfn.FORECAST.LINEAR(V$1,$D11:U11,$D$1:U$1) -> 18917.379 | W11: =_xlfn.FORECAST.LINEAR(W$1,$D11:V11,$D$1:V$1) -> 19581.115 | X11: =_xlfn.FORECAST.LINEAR(X$1,$D11:W11,$D$1:W$1) -> 20244.851 | Y11: =_xlfn.FORECAST.LINEAR(Y$1,$D11:X11,$D$1:X$1) -> 20908.587 | Z11: =_xlfn.FORECAST.LINEAR(Z$1,$D11:Y11,$D$1:Y$1) -> 21572.322 | AA11: =_xlfn.FORECAST.LINEAR(AA$1,$D11:Z11,$D$1:Z$1)*AVERAGE($L53:P53) -> 25110.204 | AB11: =_xlfn.FORECAST.LINEAR(AB$1,$D11:AA11,$D$1:AA$1)*AVERAGE($L53:Q53) -> 26387.852 | AC11: =_xlfn.FORECAST.LINEAR(AC$1,$D11:AB11,$D$1:AB$1)*AVERAGE($L53:R53) -> 27255.202 | AD11: =_xlfn.FORECAST.LINEAR(AD$1,$D11:AC11,$D$1:AC$1)*AVERAGE($L53:S53) -> 28192.342 | AE11: =_xlfn.FORECAST.LINEAR(AE$1,$D11:AD11,$D$1:AD$1)*AVERAGE($L53:T53) -> 28808.912 | AF11: =_xlfn.FORECAST.LINEAR(AF$1,$D11:AE11,$D$1:AE$1)*AVERAGE($L53:U53) -> 29386.97
A12: 55-64 | B12: females | C12: Estonia | D12: 8117 | E12: 9469 | F12: 8933 | G12: 8923 | H12: 8693 | I12: 9291 | J12: 10564 | K12: 12678 | L12: 13889 | M12: 14427 | N12: 15151 | O12: 15596 | P12: 16038 | Q12: 16761 | R12: 19654 | S12: 17998 | T12: 19300 | U12: 20732 | V12: =_xlfn.FORECAST.LINEAR(V$1,$D12:U12,$D$1:U$1) -> 21038.987 | W12: =_xlfn.FORECAST.LINEAR(W$1,$D12:V12,$D$1:V$1) -> 21813.769 | X12: =_xlfn.FORECAST.LINEAR(X$1,$D12:W12,$D$1:W$1) -> 22588.551 | Y12: =_xlfn.FORECAST.LINEAR(Y$1,$D12:X12,$D$1:X$1) -> 23363.334 | Z12: =_xlfn.FORECAST.LINEAR(Z$1,$D12:Y12,$D$1:Y$1) -> 24138.116 | AA12: =_xlfn.FORECAST.LINEAR(AA$1,$D12:Z12,$D$1:Z$1)*AVERAGE($L54:P54) -> 26811.675 | AB12: =_xlfn.FORECAST.LINEAR(AB$1,$D12:AA12,$D$1:AA$1)*AVERAGE($L54:Q54) -> 27645.092 | AC12: =_xlfn.FORECAST.LINEAR(AC$1,$D12:AB12,$D$1:AB$1)*AVERAGE($L54:R54) -> 28994.224 | AD12: =_xlfn.FORECAST.LINEAR(AD$1,$D12:AC12,$D$1:AC$1)*AVERAGE($L54:S54) -> 29773.839 | AE12: =_xlfn.FORECAST.LINEAR(AE$1,$D12:AD12,$D$1:AD$1)*AVERAGE($L54:T54) -> 30695.797 | AF12: =_xlfn.FORECAST.LINEAR(AF$1,$D12:AE12,$D$1:AE$1)*AVERAGE($L54:U54) -> 31732.472
C13: Latvia | D13: 8038 | E13: 8277 | F13: 7300 | G13: 7417 | H13: 7703 | I13: 8121 | J13: 9120 | K13: 9851 | L13: 10640 | M13: 10692 | N13: 11315 | O13: 12118 | P13: 12605 | Q13: 13521 | R13: 13866 | S13: 14319 | T13: 16161 | U13: 19059 | V13: =_xlfn.FORECAST.LINEAR(V$1,$D13:U13,$D$1:U$1) -> 16715.856 | W13: =_xlfn.FORECAST.LINEAR(W$1,$D13:V13,$D$1:V$1) -> 17305.11 | X13: =_xlfn.FORECAST.LINEAR(X$1,$D13:W13,$D$1:W$1) -> 17894.364 | Y13: =_xlfn.FORECAST.LINEAR(Y$1,$D13:X13,$D$1:X$1) -> 18483.618 | Z13: =_xlfn.FORECAST.LINEAR(Z$1,$D13:Y13,$D$1:Y$1) -> 19072.872 | AA13: =_xlfn.FORECAST.LINEAR(AA$1,$D13:Z13,$D$1:Z$1)*AVERAGE($L55:P55) -> 21217.46 | AB13: =_xlfn.FORECAST.LINEAR(AB$1,$D13:AA13,$D$1:AA$1)*AVERAGE($L55:Q55) -> 22124.988 | AC13: =_xlfn.FORECAST.LINEAR(AC$1,$D13:AB13,$D$1:AB$1)*AVERAGE($L55:R55) -> 22952.18 | AD13: =_xlfn.FORECAST.LINEAR(AD$1,$D13:AC13,$D$1:AC$1)*AVERAGE($L55:S55) -> 23757.242 | AE13: =_xlfn.FORECAST.LINEAR(AE$1,$D13:AD13,$D$1:AD$1)*AVERAGE($L55:T55) -> 24795.664 | AF13: =_xlfn.FORECAST.LINEAR(AF$1,$D13:AE13,$D$1:AE$1)*AVERAGE($L55:U55) -> 26147.955
C14: Lithuania | D14: 8332 | E14: 8723 | F14: 7820 | G14: 7244 | H14: 7915 | I14: 8619 | J14: 9687 | K14: 10270 | L14: 12403 | M14: 12569 | N14: 13043 | O14: 14588 | P14: 14994 | Q14: 17207 | R14: 17250 | S14: 17181 | T14: 17708 | U14: 18585 | V14: =_xlfn.FORECAST.LINEAR(V$1,$D14:U14,$D$1:U$1) -> 19335.229 | W14: =_xlfn.FORECAST.LINEAR(W$1,$D14:V14,$D$1:V$1) -> 20059.767 | X14: =_xlfn.FORECAST.LINEAR(X$1,$D14:W14,$D$1:W$1) -> 20784.306 | Y14: =_xlfn.FORECAST.LINEAR(Y$1,$D14:X14,$D$1:X$1) -> 21508.845 | Z14: =_xlfn.FORECAST.LINEAR(Z$1,$D14:Y14,$D$1:Y$1) -> 22233.384 | AA14: =_xlfn.FORECAST.LINEAR(AA$1,$D14:Z14,$D$1:Z$1)*AVERAGE($L56:P56) -> 25991.396 | AB14: =_xlfn.FORECAST.LINEAR(AB$1,$D14:AA14,$D$1:AA$1)*AVERAGE($L56:Q56) -> 27453.973 | AC14: =_xlfn.FORECAST.LINEAR(AC$1,$D14:AB14,$D$1:AB$1)*AVERAGE($L56:R56) -> 28636.443 | AD14: =_xlfn.FORECAST.LINEAR(AD$1,$D14:AC14,$D$1:AC$1)*AVERAGE($L56:S56) -> 29643.541 | AE14: =_xlfn.FORECAST.LINEAR(AE$1,$D14:AD14,$D$1:AD$1)*AVERAGE($L56:T56) -> 30642.576 | AF14: =_xlfn.FORECAST.LINEAR(AF$1,$D14:AE14,$D$1:AE$1)*AVERAGE($L56:U56) -> 31690.822
A15: 60+ | B15: males | C15: Estonia | D15: 7176 | E15: 8012 | F15: 7849 | G15: 7938 | H15: 8068 | I15: 8611 | J15: 9185 | K15: 10421 | L15: 11533 | M15: 11916 | N15: 12282 | O15: 13087 | P15: 13592 | Q15: 13930 | R15: 15478 | S15: 14138 | T15: 16086 | U15: 17039 | V15: =_xlfn.FORECAST.LINEAR(V$1,$D15:U15,$D$1:U$1) -> 17018.085 | W15: =_xlfn.FORECAST.LINEAR(W$1,$D15:V15,$D$1:V$1) -> 17602.79 | X15: =_xlfn.FORECAST.LINEAR(X$1,$D15:W15,$D$1:W$1) -> 18187.495 | Y15: =_xlfn.FORECAST.LINEAR(Y$1,$D15:X15,$D$1:X$1) -> 18772.2 | Z15: =_xlfn.FORECAST.LINEAR(Z$1,$D15:Y15,$D$1:Y$1) -> 19356.904 | AA15: =_xlfn.FORECAST.LINEAR(AA$1,$D15:Z15,$D$1:Z$1)*AVERAGE($L57:P57) -> 21227.929 | AB15: =_xlfn.FORECAST.LINEAR(AB$1,$D15:AA15,$D$1:AA$1)*AVERAGE($L57:Q57) -> 21860.97 | AC15: =_xlfn.FORECAST.LINEAR(AC$1,$D15:AB15,$D$1:AB$1)*AVERAGE($L57:R57) -> 22726.366 | AD15: =_xlfn.FORECAST.LINEAR(AD$1,$D15:AC15,$D$1:AC$1)*AVERAGE($L57:S57) -> 23195.325 | AE15: =_xlfn.FORECAST.LINEAR(AE$1,$D15:AD15,$D$1:AD$1)*AVERAGE($L57:T57) -> 23952.22 | AF15: =_xlfn.FORECAST.LINEAR(AF$1,$D15:AE15,$D$1:AE$1)*AVERAGE($L57:U57) -> 24753.28
C16: Latvia | D16: 6949 | E16: 7240 | F16: 6438 | G16: 7146 | H16: 7253 | I16: 7504 | J16: 8303 | K16: 8559 | L16: 9311 | M16: 9530 | N16: 10369 | O16: 10623 | P16: 11198 | Q16: 12355 | R16: 13506 | S16: 13371 | T16: 14605 | U16: 17392 | V16: =_xlfn.FORECAST.LINEAR(V$1,$D16:U16,$D$1:U$1) -> 15357.66 | W16: =_xlfn.FORECAST.LINEAR(W$1,$D16:V16,$D$1:V$1) -> 15911.964 | X16: =_xlfn.FORECAST.LINEAR(X$1,$D16:W16,$D$1:W$1) -> 16466.267 | Y16: =_xlfn.FORECAST.LINEAR(Y$1,$D16:X16,$D$1:X$1) -> 17020.57 | Z16: =_xlfn.FORECAST.LINEAR(Z$1,$D16:Y16,$D$1:Y$1) -> 17574.874 | AA16: =_xlfn.FORECAST.LINEAR(AA$1,$D16:Z16,$D$1:Z$1)*AVERAGE($L58:P58) -> 19303.001 | AB16: =_xlfn.FORECAST.LINEAR(AB$1,$D16:AA16,$D$1:AA$1)*AVERAGE($L58:Q58) -> 20221.038 | AC16: =_xlfn.FORECAST.LINEAR(AC$1,$D16:AB16,$D$1:AB$1)*AVERAGE($L58:R58) -> 21231.36 | AD16: =_xlfn.FORECAST.LINEAR(AD$1,$D16:AC16,$D$1:AC$1)*AVERAGE($L58:S58) -> 22034.464 | AE16: =_xlfn.FORECAST.LINEAR(AE$1,$D16:AD16,$D$1:AD$1)*AVERAGE($L58:T58) -> 22957.11 | AF16: =_xlfn.FORECAST.LINEAR(AF$1,$D16:AE16,$D$1:AE$1)*AVERAGE($L58:U58) -> 24200.806
C17: Lithuania | D17: 7289 | E17: 8169 | F17: 7669 | G17: 7064 | H17: 7504 | I17: 8085 | J17: 8475 | K17: 9246 | L17: 10666 | M17: 11170 | N17: 11533 | O17: 13040 | P17: 13589 | Q17: 14985 | R17: 14989 | S17: 14889 | T17: 14915 | U17: 15425 | V17: =_xlfn.FORECAST.LINEAR(V$1,$D17:U17,$D$1:U$1) -> 16495.706 | W17: =_xlfn.FORECAST.LINEAR(W$1,$D17:V17,$D$1:V$1) -> 17070.096 | X17: =_xlfn.FORECAST.LINEAR(X$1,$D17:W17,$D$1:W$1) -> 17644.486 | Y17: =_xlfn.FORECAST.LINEAR(Y$1,$D17:X17,$D$1:X$1) -> 18218.876 | Z17: =_xlfn.FORECAST.LINEAR(Z$1,$D17:Y17,$D$1:Y$1) -> 18793.266 | AA17: =_xlfn.FORECAST.LINEAR(AA$1,$D17:Z17,$D$1:Z$1)*AVERAGE($L59:P59) -> 21918.445 | AB17: =_xlfn.FORECAST.LINEAR(AB$1,$D17:AA17,$D$1:AA$1)*AVERAGE($L59:Q59) -> 23048.008 | AC17: =_xlfn.FORECAST.LINEAR(AC$1,$D17:AB17,$D$1:AB$1)*AVERAGE($L59:R59) -> 23962.024 | AD17: =_xlfn.FORECAST.LINEAR(AD$1,$D17:AC17,$D$1:AC$1)*AVERAGE($L59:S59) -> 24737.154 | AE17: =_xlfn.FORECAST.LINEAR(AE$1,$D17:AD17,$D$1:AD$1)*AVERAGE($L59:T59) -> 25444.397 | AF17: =_xlfn.FORECAST.LINEAR(AF$1,$D17:AE17,$D$1:AE$1)*AVERAGE($L59:U59) -> 26176.981
A18: 60+ | B18: females | C18: Estonia | D18: 6109 | E18: 6960 | F18: 6911 | G18: 7117 | H18: 7221 | I18: 7645 | J18: 8008 | K18: 9131 | L18: 10114 | M18: 10603 | N18: 11049 | O18: 11779 | P18: 12113 | Q18: 12453 | R18: 13896 | S18: 12795 | T18: 14214 | U18: 15454 | V18: =_xlfn.FORECAST.LINEAR(V$1,$D18:U18,$D$1:U$1) -> 15318.033 | W18: =_xlfn.FORECAST.LINEAR(W$1,$D18:V18,$D$1:V$1) -> 15856.937 | X18: =_xlfn.FORECAST.LINEAR(X$1,$D18:W18,$D$1:W$1) -> 16395.841 | Y18: =_xlfn.FORECAST.LINEAR(Y$1,$D18:X18,$D$1:X$1) -> 16934.745 | Z18: =_xlfn.FORECAST.LINEAR(Z$1,$D18:Y18,$D$1:Y$1) -> 17473.649 | AA18: =_xlfn.FORECAST.LINEAR(AA$1,$D18:Z18,$D$1:Z$1)*AVERAGE($L60:P60) -> 19225.885 | AB18: =_xlfn.FORECAST.LINEAR(AB$1,$D18:AA18,$D$1:AA$1)*AVERAGE($L60:Q60) -> 19805.011 | AC18: =_xlfn.FORECAST.LINEAR(AC$1,$D18:AB18,$D$1:AB$1)*AVERAGE($L60:R60) -> 20605.954 | AD18: =_xlfn.FORECAST.LINEAR(AD$1,$D18:AC18,$D$1:AC$1)*AVERAGE($L60:S60) -> 21063.143 | AE18: =_xlfn.FORECAST.LINEAR(AE$1,$D18:AD18,$D$1:AD$1)*AVERAGE($L60:T60) -> 21719.418 | AF18: =_xlfn.FORECAST.LINEAR(AF$1,$D18:AE18,$D$1:AE$1)*AVERAGE($L60:U60) -> 22481.328
C19: Latvia | D19: 6097 | E19: 6455 | F19: 6090 | G19: 6465 | H19: 6278 | I19: 6621 | J19: 7235 | K19: 7414 | L19: 8326 | M19: 8306 | N19: 8637 | O19: 9361 | P19: 9842 | Q19: 10419 | R19: 11145 | S19: 11473 | T19: 12800 | U19: 15108 | V19: =_xlfn.FORECAST.LINEAR(V$1,$D19:U19,$D$1:U$1) -> 13133.895 | W19: =_xlfn.FORECAST.LINEAR(W$1,$D19:V19,$D$1:V$1) -> 13592.013 | X19: =_xlfn.FORECAST.LINEAR(X$1,$D19:W19,$D$1:W$1) -> 14050.131 | Y19: =_xlfn.FORECAST.LINEAR(Y$1,$D19:X19,$D$1:X$1) -> 14508.248 | Z19: =_xlfn.FORECAST.LINEAR(Z$1,$D19:Y19,$D$1:Y$1) -> 14966.366 | AA19: =_xlfn.FORECAST.LINEAR(AA$1,$D19:Z19,$D$1:Z$1)*AVERAGE($L61:P61) -> 16525.407 | AB19: =_xlfn.FORECAST.LINEAR(AB$1,$D19:AA19,$D$1:AA$1)*AVERAGE($L61:Q61) -> 17224.118 | AC19: =_xlfn.FORECAST.LINEAR(AC$1,$D19:AB19,$D$1:AB$1)*AVERAGE($L61:R61) -> 17971.658 | AD19: =_xlfn.FORECAST.LINEAR(AD$1,$D19:AC19,$D$1:AC$1)*AVERAGE($L61:S61) -> 18667.382 | AE19: =_xlfn.FORECAST.LINEAR(AE$1,$D19:AD19,$D$1:AD$1)*AVERAGE($L61:T61) -> 19510.309 | AF19: =_xlfn.FORECAST.LINEAR(AF$1,$D19:AE19,$D$1:AE$1)*AVERAGE($L61:U61) -> 20599.718
C20: Lithuania | D20: 6373 | E20: 6977 | F20: 6749 | G20: 6318 | H20: 6484 | I20: 7242 | J20: 7671 | K20: 8096 | L20: 9165 | M20: 9359 | N20: 9744 | O20: 10618 | P20: 11279 | Q20: 12246 | R20: 12475 | S20: 12632 | T20: 13577 | U20: 14564 | V20: =_xlfn.FORECAST.LINEAR(V$1,$D20:U20,$D$1:U$1) -> 14261.444 | W20: =_xlfn.FORECAST.LINEAR(W$1,$D20:V20,$D$1:V$1) -> 14759.322 | X20: =_xlfn.FORECAST.LINEAR(X$1,$D20:W20,$D$1:W$1) -> 15257.199 | Y20: =_xlfn.FORECAST.LINEAR(Y$1,$D20:X20,$D$1:X$1) -> 15755.076 | Z20: =_xlfn.FORECAST.LINEAR(Z$1,$D20:Y20,$D$1:Y$1) -> 16252.953 | AA20: =_xlfn.FORECAST.LINEAR(AA$1,$D20:Z20,$D$1:Z$1)*AVERAGE($L62:P62) -> 18321.355 | AB20: =_xlfn.FORECAST.LINEAR(AB$1,$D20:AA20,$D$1:AA$1)*AVERAGE($L62:Q62) -> 19196.599 | AC20: =_xlfn.FORECAST.LINEAR(AC$1,$D20:AB20,$D$1:AB$1)*AVERAGE($L62:R62) -> 19953.622 | AD20: =_xlfn.FORECAST.LINEAR(AD$1,$D20:AC20,$D$1:AC$1)*AVERAGE($L62:S62) -> 20632.649 | AE20: =_xlfn.FORECAST.LINEAR(AE$1,$D20:AD20,$D$1:AD$1)*AVERAGE($L62:T62) -> 21398.165 | AF20: =_xlfn.FORECAST.LINEAR(AF$1,$D20:AE20,$D$1:AE$1)*AVERAGE($L62:U62) -> 22227.671
A21: The overlapbetween the categories 55-64 and 60+ is due to limited data availability, and, subsequently, tolerated.
A23: Forecast 5 year ahead
